data/output-ground-truth/UBSG.txt
PASSIVE BUY 1460.00 @ 36.71
PASSIVE BUY 980.00 @ 36.67
PASSIVE BUY 2620.00 @ 36.76
PASSIVE BUY 2780.00 @ 36.90
PASSIVE BUY 1140.00 @ 36.93
PASSIVE BUY 1460.00 @ 37.10
PASSIVE SELL 1980.00 @ 37.14
AGGRESSIVE SELL 1300.00 @ 37.10
PASSIVE SELL 1940.00 @ 37.11
AGGRESSIVE SELL 1300.00 @ 37.04
AGGRESSIVE SELL 740.00 @ 36.93
PASSIVE SELL 1500.00 @ 37.05
PASSIVE SELL 1700.00 @ 37.01
PASSIVE SELL 2140.00 @ 37.11
PASSIVE BUY 2700.00 @ 36.98
PASSIVE SELL 1940.00 @ 37.07
AGGRESSIVE SELL 940.00 @ 36.98
AGGRESSIVE BUY 2860.00 @ 37.01
CANCEL BUY 1460.00 @ 36.71
CANCEL BUY 980.00 @ 36.67
CANCEL BUY 2620.00 @ 36.76
CANCEL BUY 2780.00 @ 36.90
CANCEL BUY 400.00 @ 36.93
CANCEL BUY 1760.00 @ 36.98
CANCEL BUY 1160.00 @ 37.01
PASSIVE BUY 1940.00 @ 37.00
PASSIVE SELL 1180.00 @ 37.16
PASSIVE SELL 380.00 @ 37.14
AGGRESSIVE SELL 860.00 @ 37.00
PASSIVE SELL 1540.00 @ 37.11
AGGRESSIVE BUY 2220.00 @ 37.05
PASSIVE SELL 820.00 @ 37.01
PASSIVE BUY 2020.00 @ 36.92
PASSIVE SELL 1780.00 @ 37.02
CANCEL SELL 1180.00 @ 37.16
PASSIVE BUY 2900.00 @ 36.96
AGGRESSIVE BUY 1340.00 @ 37.02
AGGRESSIVE BUY 780.00 @ 37.02
PASSIVE BUY 2020.00 @ 36.98
PASSIVE BUY 1420.00 @ 36.96
PASSIVE SELL 2300.00 @ 37.12
PASSIVE SELL 2260.00 @ 37.11
PASSIVE SELL 420.00 @ 37.11
PASSIVE SELL 940.00 @ 37.07
PASSIVE BUY 2420.00 @ 36.90
AGGRESSIVE BUY 1580.00 @ 37.07
PASSIVE SELL 1060.00 @ 37.08
PASSIVE SELL 860.00 @ 37.06
PASSIVE SELL 1660.00 @ 37.06
AGGRESSIVE SELL 540.00 @ 37.00
PASSIVE BUY 2140.00 @ 36.87
PASSIVE BUY 1940.00 @ 36.94
CANCEL BUY 540.00 @ 37.00
CANCEL BUY 2020.00 @ 36.92
CANCEL BUY -2900.00 @ 36.96
CANCEL BUY 2020.00 @ 36.98
CANCEL BUY 1420.00 @ 36.96
CANCEL BUY 2420.00 @ 36.90
CANCEL BUY 2140.00 @ 36.87
CANCEL BUY 1940.00 @ 36.94
PASSIVE BUY 1660.00 @ 36.94
AGGRESSIVE BUY 2340.00 @ 37.06
PASSIVE BUY 2020.00 @ 36.91
PASSIVE SELL 1220.00 @ 37.07
AGGRESSIVE SELL 460.00 @ 36.94
PASSIVE SELL 1340.00 @ 37.13
CANCEL SELL -1980.00 @ 37.14
CANCEL SELL 380.00 @ 37.14
PASSIVE SELL 980.00 @ 37.06
PASSIVE BUY 900.00 @ 36.84
AGGRESSIVE SELL 740.00 @ 36.94
PASSIVE BUY 780.00 @ 36.97
PASSIVE SELL 860.00 @ 37.03
CANCEL SELL 1340.00 @ 37.13
AGGRESSIVE BUY 1620.00 @ 37.06
AGGRESSIVE SELL 1180.00 @ 36.94
AGGRESSIVE SELL 980.00 @ 36.92
PASSIVE SELL 1220.00 @ 37.05
CANCEL SELL 2300.00 @ 37.12
AGGRESSIVE BUY 1700.00 @ 37.02
PASSIVE BUY 2860.00 @ 36.99
AGGRESSIVE SELL 940.00 @ 36.99
AGGRESSIVE BUY 1940.00 @ 37.07
AGGRESSIVE SELL 1500.00 @ 36.99
AGGRESSIVE BUY 2140.00 @ 37.07
AGGRESSIVE BUY 2260.00 @ 37.09
AGGRESSIVE BUY 1420.00 @ 37.11
PASSIVE BUY 2500.00 @ 36.97
AGGRESSIVE SELL 1700.00 @ 37.04
AGGRESSIVE SELL 2180.00 @ 36.97
AGGRESSIVE BUY 1740.00 @ 37.11
PASSIVE SELL 1860.00 @ 37.09
AGGRESSIVE SELL 1660.00 @ 36.94
PASSIVE BUY 1740.00 @ 36.91
PASSIVE SELL 580.00 @ 36.99
PASSIVE BUY 1300.00 @ 36.85
AGGRESSIVE BUY 2540.00 @ 37.08
AGGRESSIVE SELL 1940.00 @ 36.99
PASSIVE BUY 2220.00 @ 36.97
PASSIVE SELL 540.00 @ 37.04
AGGRESSIVE SELL 780.00 @ 36.97
AGGRESSIVE SELL 540.00 @ 36.97
AGGRESSIVE SELL 2300.00 @ 36.91
AGGRESSIVE BUY 1060.00 @ 37.03
PASSIVE BUY 2860.00 @ 36.99
AGGRESSIVE BUY 1100.00 @ 37.09
AGGRESSIVE BUY 1860.00 @ 37.10
PASSIVE SELL 860.00 @ 37.11
PASSIVE SELL 1020.00 @ 37.19
PASSIVE SELL 1500.00 @ 37.18
AGGRESSIVE SELL 660.00 @ 37.03
AGGRESSIVE BUY 2580.00 @ 37.11
PASSIVE BUY 2140.00 @ 36.96
PASSIVE SELL 1580.00 @ 37.13
PASSIVE BUY 2580.00 @ 37.10
CANCEL BUY -620.00 @ 36.91
CANCEL BUY 900.00 @ 36.84
CANCEL BUY 1740.00 @ 36.91
CANCEL BUY 1300.00 @ 36.85
CANCEL BUY 840.00 @ 37.03
CANCEL BUY 2860.00 @ 36.99
CANCEL BUY 2140.00 @ 36.96
CANCEL BUY 2580.00 @ 37.10
PASSIVE SELL 460.00 @ 37.05
AGGRESSIVE BUY 1540.00 @ 37.10
PASSIVE SELL 1660.00 @ 37.24
AGGRESSIVE SELL 1220.00 @ 36.97
AGGRESSIVE BUY 1700.00 @ 37.04
PASSIVE BUY 1180.00 @ 37.08
PASSIVE SELL 1100.00 @ 37.17
AGGRESSIVE BUY 1100.00 @ 37.11
PASSIVE SELL 1460.00 @ 37.18
AGGRESSIVE BUY 2420.00 @ 37.11
AGGRESSIVE BUY 1380.00 @ 37.13
PASSIVE SELL 1340.00 @ 37.12
PASSIVE SELL 1540.00 @ 37.19
PASSIVE SELL 700.00 @ 37.15
CANCEL SELL 1660.00 @ 37.24
PASSIVE BUY 1180.00 @ 37.02
PASSIVE SELL 1740.00 @ 37.21
CANCEL SELL 1740.00 @ 37.21
AGGRESSIVE SELL 780.00 @ 37.08
AGGRESSIVE SELL 1660.00 @ 37.04
PASSIVE BUY 1940.00 @ 37.02
PASSIVE BUY 860.00 @ 36.96
PASSIVE BUY 2340.00 @ 36.97
PASSIVE SELL 1460.00 @ 37.13
PASSIVE SELL 700.00 @ 37.20
CANCEL SELL 700.00 @ 37.20
PASSIVE SELL 1500.00 @ 37.17
PASSIVE BUY 2100.00 @ 37.10
AGGRESSIVE BUY 1100.00 @ 37.12
AGGRESSIVE SELL 900.00 @ 37.10
PASSIVE BUY 780.00 @ 37.03
AGGRESSIVE BUY 2340.00 @ 37.13
AGGRESSIVE BUY 1980.00 @ 37.17
AGGRESSIVE SELL 1140.00 @ 37.10
AGGRESSIVE BUY 1060.00 @ 37.17
PASSIVE BUY 980.00 @ 37.13
CANCEL BUY 300.00 @ 37.04
CANCEL BUY -1180.00 @ 37.02
CANCEL BUY 1940.00 @ 37.02
CANCEL BUY 860.00 @ 36.96
CANCEL BUY 2340.00 @ 36.97
CANCEL BUY 60.00 @ 37.10
CANCEL BUY 780.00 @ 37.03
CANCEL BUY 980.00 @ 37.13
PASSIVE SELL 1540.00 @ 37.03
AGGRESSIVE BUY 2780.00 @ 37.18
PASSIVE SELL 1100.00 @ 37.08
PASSIVE SELL 1700.00 @ 37.05
PASSIVE SELL 380.00 @ 36.94
AGGRESSIVE BUY 2900.00 @ 37.08
PASSIVE SELL 380.00 @ 37.14
PASSIVE SELL 660.00 @ 37.17
PASSIVE SELL 1980.00 @ 37.04
PASSIVE SELL 1620.00 @ 37.07
CANCEL SELL -1020.00 @ 37.19
CANCEL SELL 1540.00 @ 37.19
AGGRESSIVE BUY 2660.00 @ 37.07
AGGRESSIVE BUY 1860.00 @ 37.15
AGGRESSIVE BUY 1020.00 @ 37.18
AGGRESSIVE BUY 1420.00 @ 37.18
PASSIVE SELL 1580.00 @ 37.18
PASSIVE BUY 1540.00 @ 37.04
AGGRESSIVE SELL 1340.00 @ 37.06
AGGRESSIVE BUY 2620.00 @ 37.06
PASSIVE BUY 2020.00 @ 36.97
PASSIVE SELL 1780.00 @ 37.16
PASSIVE SELL 2020.00 @ 37.26
PASSIVE SELL 1500.00 @ 37.13
PASSIVE SELL 2260.00 @ 37.20
PASSIVE SELL 1780.00 @ 37.25
AGGRESSIVE SELL 1140.00 @ 37.06
PASSIVE BUY 1700.00 @ 37.03
PASSIVE SELL 700.00 @ 37.10
CANCEL SELL 2020.00 @ 37.26
PASSIVE BUY 2420.00 @ 37.03
PASSIVE SELL 380.00 @ 37.09
CANCEL SELL 1780.00 @ 37.25
AGGRESSIVE BUY 980.00 @ 37.10
PASSIVE BUY 2100.00 @ 37.05
AGGRESSIVE SELL 940.00 @ 37.05
PASSIVE BUY 1500.00 @ 36.94
PASSIVE SELL 2060.00 @ 37.20
PASSIVE SELL 700.00 @ 37.21
AGGRESSIVE BUY 2580.00 @ 37.11
AGGRESSIVE SELL 2180.00 @ 37.11
AGGRESSIVE BUY 2180.00 @ 37.16
AGGRESSIVE BUY 1180.00 @ 37.18
PASSIVE BUY 1780.00 @ 37.03
AGGRESSIVE SELL 1100.00 @ 37.11
PASSIVE BUY 1140.00 @ 37.06
PASSIVE SELL 700.00 @ 37.22
PASSIVE SELL 2300.00 @ 37.09
PASSIVE SELL 1860.00 @ 37.12
CANCEL SELL 700.00 @ 37.22
AGGRESSIVE SELL 1180.00 @ 37.05
AGGRESSIVE BUY 780.00 @ 37.09
PASSIVE SELL 2220.00 @ 37.09
AGGRESSIVE SELL 580.00 @ 37.05
PASSIVE SELL 900.00 @ 37.09
PASSIVE SELL 1980.00 @ 37.17
CANCEL SELL 700.00 @ 37.21
AGGRESSIVE BUY 940.00 @ 37.09
PASSIVE BUY 2540.00 @ 37.07
AGGRESSIVE BUY 2380.00 @ 37.09
AGGRESSIVE BUY 1740.00 @ 37.11
AGGRESSIVE SELL 980.00 @ 37.07
AGGRESSIVE BUY 2940.00 @ 37.15
CANCEL BUY 1540.00 @ 37.04
CANCEL BUY 2020.00 @ 36.97
CANCEL BUY -1700.00 @ 37.03
CANCEL BUY -2420.00 @ 37.03
CANCEL BUY 940.00 @ 37.05
CANCEL BUY 1500.00 @ 36.94
CANCEL BUY 1780.00 @ 37.03
CANCEL BUY 1560.00 @ 37.07
CANCEL BUY 700.00 @ 37.15
PASSIVE BUY 1820.00 @ 37.14
PASSIVE BUY 2420.00 @ 37.00
AGGRESSIVE BUY 980.00 @ 37.17
PASSIVE BUY 1780.00 @ 37.14
PASSIVE SELL 1900.00 @ 37.25
PASSIVE SELL 2100.00 @ 37.24
AGGRESSIVE SELL 1980.00 @ 37.14
AGGRESSIVE SELL 2140.00 @ 37.12
AGGRESSIVE BUY 1980.00 @ 37.16
PASSIVE BUY 820.00 @ 37.09
AGGRESSIVE BUY 2540.00 @ 37.18
AGGRESSIVE SELL 1060.00 @ 37.16
PASSIVE BUY 1540.00 @ 37.16
PASSIVE SELL 1700.00 @ 37.21
PASSIVE BUY 2180.00 @ 37.05
AGGRESSIVE BUY 2660.00 @ 37.20
PASSIVE BUY 1580.00 @ 37.18
PASSIVE BUY 1780.00 @ 37.12
PASSIVE BUY 820.00 @ 37.15
CANCEL BUY 2420.00 @ 37.00
CANCEL BUY -400.00 @ 37.16
CANCEL BUY 820.00 @ 37.09
CANCEL BUY 1540.00 @ 37.16
CANCEL BUY 2180.00 @ 37.05
CANCEL BUY 1580.00 @ 37.18
CANCEL BUY 1780.00 @ 37.12
CANCEL BUY 820.00 @ 37.15
PASSIVE SELL 2180.00 @ 37.22
AGGRESSIVE BUY 2700.00 @ 37.20
AGGRESSIVE BUY 2620.00 @ 37.22
PASSIVE SELL 1100.00 @ 37.25
PASSIVE BUY 2420.00 @ 37.13
AGGRESSIVE BUY 1340.00 @ 37.24
PASSIVE BUY 740.00 @ 37.10
PASSIVE BUY 2740.00 @ 37.09
PASSIVE BUY 1420.00 @ 37.12
PASSIVE SELL 700.00 @ 37.24
PASSIVE BUY 2300.00 @ 37.09
