data/output-ground-truth/ZURN.txt
PASSIVE BUY 2540.00 @ 79.93
PASSIVE BUY 1260.00 @ 80.02
PASSIVE BUY 1500.00 @ 79.91
PASSIVE SELL 1940.00 @ 80.20
PASSIVE BUY 1260.00 @ 80.01
PASSIVE BUY 1500.00 @ 80.13
PASSIVE SELL 1380.00 @ 80.15
PASSIVE BUY 2460.00 @ 80.08
PASSIVE SELL 900.00 @ 80.24
PASSIVE SELL 1020.00 @ 80.22
AGGRESSIVE SELL 1700.00 @ 80.08
PASSIVE SELL 1660.00 @ 80.21
AGGRESSIVE SELL 2140.00 @ 80.08
AGGRESSIVE SELL 580.00 @ 80.05
AGGRESSIVE SELL 1660.00 @ 80.01
PASSIVE BUY 2780.00 @ 79.94
AGGRESSIVE BUY 1620.00 @ 80.15
PASSIVE BUY 1820.00 @ 80.05
AGGRESSIVE SELL 1660.00 @ 80.05
PASSIVE BUY 1260.00 @ 80.12
PASSIVE SELL 580.00 @ 80.23
AGGRESSIVE BUY 2580.00 @ 80.18
CANCEL BUY 2540.00 @ 79.93
CANCEL BUY 1500.00 @ 79.91
CANCEL BUY 860.00 @ 80.01
CANCEL BUY 2780.00 @ 79.94
CANCEL BUY 160.00 @ 80.05
CANCEL BUY 1260.00 @ 80.12
CANCEL BUY 2360.00 @ 80.18
AGGRESSIVE BUY 1620.00 @ 80.20
AGGRESSIVE BUY 2060.00 @ 80.22
PASSIVE BUY 940.00 @ 80.01
PASSIVE SELL 1740.00 @ 80.09
PASSIVE SELL 1940.00 @ 80.11
PASSIVE SELL 860.00 @ 80.08
PASSIVE SELL 1340.00 @ 80.06
CANCEL SELL 900.00 @ 80.24
AGGRESSIVE SELL 860.00 @ 80.01
AGGRESSIVE BUY 2900.00 @ 80.09
PASSIVE SELL 940.00 @ 80.04
PASSIVE SELL 700.00 @ 80.05
PASSIVE SELL 1740.00 @ 80.10
CANCEL SELL 580.00 @ 80.23
PASSIVE SELL 420.00 @ 80.07
CANCEL SELL 940.00 @ 80.22
PASSIVE SELL 940.00 @ 80.13
CANCEL SELL 940.00 @ 80.13
PASSIVE SELL 780.00 @ 80.08
CANCEL SELL 1940.00 @ 80.11
PASSIVE BUY 2420.00 @ 79.90
PASSIVE BUY 780.00 @ 80.03
AGGRESSIVE BUY 2860.00 @ 80.05
PASSIVE SELL 1260.00 @ 80.13
AGGRESSIVE SELL 2020.00 @ 80.01
PASSIVE SELL 740.00 @ 80.05
PASSIVE SELL 1380.00 @ 80.17
CANCEL SELL 1380.00 @ 80.17
AGGRESSIVE SELL 380.00 @ 79.90
PASSIVE SELL 2300.00 @ 79.94
CANCEL SELL 1260.00 @ 80.13
AGGRESSIVE BUY 1620.00 @ 79.94
PASSIVE SELL 1340.00 @ 80.02
CANCEL SELL 1740.00 @ 80.10
AGGRESSIVE SELL 660.00 @ 79.90
PASSIVE BUY 2500.00 @ 79.86
PASSIVE BUY 2620.00 @ 79.80
AGGRESSIVE SELL 1740.00 @ 79.86
AGGRESSIVE BUY 1100.00 @ 79.94
PASSIVE BUY 2180.00 @ 79.98
AGGRESSIVE BUY 2540.00 @ 80.08
AGGRESSIVE SELL 580.00 @ 79.98
PASSIVE BUY 1620.00 @ 80.06
AGGRESSIVE SELL 620.00 @ 80.06
AGGRESSIVE BUY 2700.00 @ 80.13
PASSIVE SELL 420.00 @ 80.34
PASSIVE BUY 2620.00 @ 80.16
CANCEL BUY 2200.00 @ 79.86
CANCEL BUY 2620.00 @ 79.80
CANCEL BUY 420.00 @ 79.94
CANCEL BUY 1600.00 @ 79.98
CANCEL BUY 1000.00 @ 80.06
CANCEL BUY 920.00 @ 80.13
CANCEL BUY 2620.00 @ 80.16
PASSIVE SELL 1100.00 @ 80.17
PASSIVE SELL 580.00 @ 80.29
AGGRESSIVE BUY 2060.00 @ 80.28
PASSIVE SELL 2100.00 @ 80.43
PASSIVE BUY 2820.00 @ 80.28
PASSIVE BUY 1420.00 @ 80.21
PASSIVE SELL 620.00 @ 80.43
AGGRESSIVE BUY 1860.00 @ 80.33
PASSIVE SELL 1780.00 @ 80.42
AGGRESSIVE SELL 1860.00 @ 80.28
PASSIVE BUY 900.00 @ 80.30
PASSIVE BUY 2740.00 @ 80.17
AGGRESSIVE SELL 1740.00 @ 80.28
PASSIVE BUY 980.00 @ 80.33
AGGRESSIVE SELL 1820.00 @ 80.28
PASSIVE BUY 740.00 @ 80.24
AGGRESSIVE SELL 1980.00 @ 80.25
PASSIVE BUY 1140.00 @ 80.16
AGGRESSIVE BUY 1940.00 @ 80.39
AGGRESSIVE BUY 1780.00 @ 80.42
AGGRESSIVE BUY 2100.00 @ 80.43
PASSIVE BUY 1860.00 @ 80.29
PASSIVE BUY 2620.00 @ 80.38
CANCEL BUY 1420.00 @ 80.21
CANCEL BUY 2740.00 @ 80.17
CANCEL BUY 740.00 @ 80.24
CANCEL BUY 1140.00 @ 80.16
CANCEL BUY 1060.00 @ 80.39
CANCEL BUY 1860.00 @ 80.29
CANCEL BUY 2620.00 @ 80.38
PASSIVE SELL 780.00 @ 80.37
PASSIVE SELL 660.00 @ 80.29
AGGRESSIVE BUY 1060.00 @ 80.37
AGGRESSIVE BUY 2180.00 @ 80.52
PASSIVE SELL 1460.00 @ 80.63
PASSIVE SELL 1140.00 @ 80.64
PASSIVE SELL 1860.00 @ 80.72
PASSIVE BUY 2220.00 @ 80.55
PASSIVE BUY 1620.00 @ 80.44
PASSIVE SELL 1500.00 @ 80.58
AGGRESSIVE SELL 2020.00 @ 80.55
AGGRESSIVE BUY 1900.00 @ 80.63
PASSIVE SELL 1100.00 @ 80.72
PASSIVE SELL 1820.00 @ 80.63
PASSIVE BUY 2180.00 @ 80.57
AGGRESSIVE SELL 1500.00 @ 80.57
PASSIVE SELL 820.00 @ 80.60
AGGRESSIVE SELL 1380.00 @ 80.53
PASSIVE BUY 2140.00 @ 80.42
AGGRESSIVE BUY 2380.00 @ 80.56
PASSIVE BUY 2660.00 @ 80.45
PASSIVE SELL 1260.00 @ 80.62
AGGRESSIVE SELL 1540.00 @ 80.56
AGGRESSIVE SELL 620.00 @ 80.52
AGGRESSIVE BUY 1260.00 @ 80.62
PASSIVE BUY 1180.00 @ 80.44
PASSIVE SELL 2100.00 @ 80.67
AGGRESSIVE BUY 2500.00 @ 80.63
PASSIVE SELL 820.00 @ 80.66
PASSIVE SELL 580.00 @ 80.71
PASSIVE SELL 1060.00 @ 80.69
CANCEL SELL -1860.00 @ 80.72
CANCEL SELL 1100.00 @ 80.72
PASSIVE BUY 1140.00 @ 80.62
AGGRESSIVE SELL 2220.00 @ 80.55
CANCEL SELL 580.00 @ 80.71
AGGRESSIVE SELL 1980.00 @ 80.49
CANCEL SELL 1060.00 @ 80.69
PASSIVE BUY 2340.00 @ 80.40
PASSIVE SELL 1420.00 @ 80.61
CANCEL SELL 2100.00 @ 80.67
AGGRESSIVE SELL 1420.00 @ 80.45
PASSIVE BUY 2260.00 @ 80.47
PASSIVE SELL 1140.00 @ 80.62
CANCEL SELL 820.00 @ 80.66
AGGRESSIVE BUY 900.00 @ 80.49
PASSIVE SELL 1820.00 @ 80.51
CANCEL SELL 1140.00 @ 80.64
AGGRESSIVE SELL 2180.00 @ 80.47
PASSIVE SELL 1540.00 @ 80.51
AGGRESSIVE SELL 1740.00 @ 80.47
CANCEL SELL 1200.00 @ 80.63
AGGRESSIVE BUY 1420.00 @ 80.47
AGGRESSIVE BUY 2780.00 @ 80.47
AGGRESSIVE BUY 1340.00 @ 80.50
PASSIVE BUY 1060.00 @ 80.50
PASSIVE BUY 2860.00 @ 80.36
CANCEL BUY -1620.00 @ 80.44
CANCEL BUY 2140.00 @ 80.42
CANCEL BUY 1240.00 @ 80.45
CANCEL BUY 1180.00 @ 80.44
CANCEL BUY 2340.00 @ 80.40
CANCEL BUY 2540.00 @ 80.47
CANCEL BUY -1160.00 @ 80.50
CANCEL BUY 1060.00 @ 80.50
CANCEL BUY 2860.00 @ 80.36
PASSIVE BUY 2620.00 @ 80.48
PASSIVE SELL 900.00 @ 80.65
PASSIVE SELL 780.00 @ 80.64
AGGRESSIVE BUY 1100.00 @ 80.51
AGGRESSIVE BUY 2100.00 @ 80.51
PASSIVE SELL 540.00 @ 80.53
CANCEL SELL 900.00 @ 80.65
AGGRESSIVE BUY 2420.00 @ 80.55
PASSIVE SELL 1020.00 @ 80.60
PASSIVE SELL 580.00 @ 80.66
PASSIVE BUY 1220.00 @ 80.51
PASSIVE BUY 2780.00 @ 80.44
PASSIVE SELL 1740.00 @ 80.70
PASSIVE BUY 1740.00 @ 80.48
PASSIVE BUY 2900.00 @ 80.50
PASSIVE BUY 1540.00 @ 80.46
PASSIVE BUY 1700.00 @ 80.50
PASSIVE SELL 1700.00 @ 80.56
CANCEL SELL 1740.00 @ 80.70
AGGRESSIVE SELL 1580.00 @ 80.51
PASSIVE SELL 500.00 @ 80.70
CANCEL SELL 500.00 @ 80.70
PASSIVE SELL 1980.00 @ 80.62
PASSIVE BUY 1580.00 @ 80.51
PASSIVE SELL 1900.00 @ 80.52
CANCEL SELL 580.00 @ 80.66
AGGRESSIVE BUY 1780.00 @ 80.52
AGGRESSIVE BUY 1460.00 @ 80.56
PASSIVE SELL 380.00 @ 80.54
PASSIVE BUY 2900.00 @ 80.41
AGGRESSIVE BUY 1820.00 @ 80.61
PASSIVE SELL 1420.00 @ 80.55
AGGRESSIVE BUY 1380.00 @ 80.55
AGGRESSIVE SELL 1100.00 @ 80.51
PASSIVE SELL 2100.00 @ 80.57
AGGRESSIVE SELL 2060.00 @ 80.50
PASSIVE SELL 1460.00 @ 80.53
PASSIVE SELL 1300.00 @ 80.55
PASSIVE BUY 2220.00 @ 80.40
PASSIVE BUY 2420.00 @ 80.52
CANCEL BUY -2620.00 @ 80.48
CANCEL BUY 2780.00 @ 80.44
CANCEL BUY 1740.00 @ 80.48
CANCEL BUY -1600.00 @ 80.50
CANCEL BUY 1540.00 @ 80.46
CANCEL BUY 1700.00 @ 80.50
CANCEL BUY 2900.00 @ 80.41
CANCEL BUY 2220.00 @ 80.40
CANCEL BUY 2420.00 @ 80.52
AGGRESSIVE BUY 1620.00 @ 80.54
AGGRESSIVE BUY 2940.00 @ 80.57
PASSIVE BUY 740.00 @ 80.48
AGGRESSIVE BUY 2380.00 @ 80.62
PASSIVE BUY 2220.00 @ 80.42
PASSIVE SELL 2220.00 @ 80.62
PASSIVE BUY 2020.00 @ 80.46
PASSIVE BUY 2700.00 @ 80.51
PASSIVE SELL 1940.00 @ 80.70
PASSIVE SELL 1780.00 @ 80.60
PASSIVE SELL 900.00 @ 80.65
PASSIVE BUY 1940.00 @ 80.42
PASSIVE SELL 380.00 @ 80.63
AGGRESSIVE SELL 1580.00 @ 80.52
CANCEL SELL 1940.00 @ 80.70
AGGRESSIVE SELL 1860.00 @ 80.51
PASSIVE SELL 2220.00 @ 80.58
CANCEL SELL 900.00 @ 80.65
PASSIVE SELL 780.00 @ 80.59
CANCEL SELL 780.00 @ 80.64
AGGRESSIVE SELL 1020.00 @ 80.48
PASSIVE BUY 2820.00 @ 80.49
PASSIVE BUY 2460.00 @ 80.44
AGGRESSIVE SELL 780.00 @ 80.49
PASSIVE BUY 2660.00 @ 80.50
PASSIVE SELL 1700.00 @ 80.64
CANCEL SELL 1700.00 @ 80.64
PASSIVE SELL 660.00 @ 80.56
CANCEL SELL 380.00 @ 80.63
PASSIVE BUY 2660.00 @ 80.47
CANCEL BUY 560.00 @ 80.48
CANCEL BUY -2220.00 @ 80.42
CANCEL BUY 2020.00 @ 80.46
CANCEL BUY 1940.00 @ 80.42
CANCEL BUY 2040.00 @ 80.49
CANCEL BUY 2460.00 @ 80.44
CANCEL BUY 2660.00 @ 80.50
CANCEL BUY 2660.00 @ 80.47
AGGRESSIVE BUY 2780.00 @ 80.58
PASSIVE BUY 1260.00 @ 80.43
PASSIVE SELL 780.00 @ 80.54
AGGRESSIVE SELL 900.00 @ 80.43
PASSIVE BUY 1060.00 @ 80.44
PASSIVE SELL 780.00 @ 80.49
PASSIVE BUY 2620.00 @ 80.46
PASSIVE SELL 860.00 @ 80.57
CANCEL SELL -620.00 @ 80.62
CANCEL SELL -1980.00 @ 80.62
CANCEL SELL 2220.00 @ 80.62
PASSIVE BUY 940.00 @ 80.35
PASSIVE SELL 2180.00 @ 80.51
